<mujoco model="h1">
    <compiler angle="radian" autolimits="true"/>
    <keyframe>
        <key name="home" qpos="     
        0 0 0 
        0 0 0 0 0 0 0 0 0 
        -0.0750015 0.0750015 0.16667 0.16667 0.13489357 -0.04105263 -0.253 0.4388203 0.4388203 0.4372464 0.4372464 0.85 0.85 0.85 0.85 0.65 0.12136164 0.19417863 0.29126793 
        -0.0750015 -0.0750015 -0.16667 0.16667 -0.13489357 -0.04105263 0.253 0.44075602 0.44075602 0.43895265 0.43895265 0.85 0.85 0.85 0.85 0.65 0.12026816 0.19242907 0.2886436       
        0 
        0.4 0 1.325 1 0 0 0
        "/>
    </keyframe>

    <asset>
        <mesh name="pelvis" file="meshes/pelvis.STL" />
        <mesh name="left_hip_yaw_link" file="meshes/left_hip_yaw_link.STL" />
        <mesh name="left_hip_roll_link" file="meshes/left_hip_roll_link.STL" />
        <mesh name="left_hip_pitch_link" file="meshes/left_hip_pitch_link.STL" />
        <mesh name="left_knee_link" file="meshes/left_knee_link.STL" />
        <mesh name="left_ankle_pitch_link" file="meshes/left_ankle_pitch_link.STL" />
        <mesh name="left_ankle_roll_link" file="meshes/left_ankle_roll_link.STL" />
        <mesh name="right_hip_yaw_link" file="meshes/right_hip_yaw_link.STL" />
        <mesh name="right_hip_roll_link" file="meshes/right_hip_roll_link.STL" />
        <mesh name="right_hip_pitch_link" file="meshes/right_hip_pitch_link.STL" />
        <mesh name="right_knee_link" file="meshes/right_knee_link.STL" />
        <mesh name="right_ankle_pitch_link" file="meshes/right_ankle_pitch_link.STL" />
        <mesh name="right_ankle_roll_link" file="meshes/right_ankle_roll_link.STL" />
        <mesh name="torso_link" file="meshes/torso_link.STL" />
        <mesh name="left_shoulder_pitch_link" file="meshes/left_shoulder_pitch_link.STL" />
        <mesh name="left_shoulder_roll_link" file="meshes/left_shoulder_roll_link.STL" />
        <mesh name="left_shoulder_yaw_link" file="meshes/left_shoulder_yaw_link.STL" />
        <mesh name="left_elbow_pitch_link" file="meshes/left_elbow_pitch_link.STL" />
        <mesh name="left_elbow_roll_link" file="meshes/left_elbow_roll_link.STL" />
        <mesh name="left_wrist_pitch_link" file="meshes/left_wrist_pitch_link.STL" />
        <mesh name="wrist_yaw_link" file="meshes/wrist_yaw_link.STL" />
        <mesh name="L_hand_base_link" file="meshes/L_hand_base_link.STL" />
        <mesh name="Link11_L" file="meshes/Link11_L.STL" />
        <mesh name="Link12_L" file="meshes/Link12_L.STL" />
        <mesh name="Link13_L" file="meshes/Link13_L.STL" />
        <mesh name="Link14_L" file="meshes/Link14_L.STL" />
        <mesh name="Link15_L" file="meshes/Link15_L.STL" />
        <mesh name="Link16_L" file="meshes/Link16_L.STL" />
        <mesh name="Link17_L" file="meshes/Link17_L.STL" />
        <mesh name="Link18_L" file="meshes/Link18_L.STL" />
        <mesh name="Link19_L" file="meshes/Link19_L.STL" />
        <mesh name="Link20_L" file="meshes/Link20_L.STL" />
        <mesh name="Link21_L" file="meshes/Link21_L.STL" />
        <mesh name="Link22_L" file="meshes/Link22_L.STL" />
        <mesh name="right_shoulder_pitch_link" file="meshes/right_shoulder_pitch_link.STL" />
        <mesh name="right_shoulder_roll_link" file="meshes/right_shoulder_roll_link.STL" />
        <mesh name="right_shoulder_yaw_link" file="meshes/right_shoulder_yaw_link.STL" />
        <mesh name="right_elbow_pitch_link" file="meshes/right_elbow_pitch_link.STL" />
        <mesh name="right_elbow_roll_link" file="meshes/right_elbow_roll_link.STL" />
        <mesh name="right_wrist_pitch_link" file="meshes/right_wrist_pitch_link.STL" />
        <mesh name="R_hand_base_link" file="meshes/R_hand_base_link.STL" />
        <mesh name="Link11_R" file="meshes/Link11_R.STL" />
        <mesh name="Link12_R" file="meshes/Link12_R.STL" />
        <mesh name="Link13_R" file="meshes/Link13_R.STL" />
        <mesh name="Link14_R" file="meshes/Link14_R.STL" />
        <mesh name="Link15_R" file="meshes/Link15_R.STL" />
        <mesh name="Link16_R" file="meshes/Link16_R.STL" />
        <mesh name="Link17_R" file="meshes/Link17_R.STL" />
        <mesh name="Link18_R" file="meshes/Link18_R.STL" />
        <mesh name="Link19_R" file="meshes/Link19_R.STL" />
        <mesh name="Link20_R" file="meshes/Link20_R.STL" />
        <mesh name="Link21_R" file="meshes/Link21_R.STL" />
        <mesh name="Link22_R" file="meshes/Link22_R.STL" />
        <mesh name="logo_link" file="meshes/logo_link.STL" />
        <material name="floor" reflectance=".1"/>

        <mesh name="mug_visual" file="../../assets/objects/ycb/025_mug/mug_visual.obj" scale="0.01 0.01 0.01"/>
        <mesh name="mug_collision" file="../../assets/objects/ycb/025_mug/mug_collision_tw.obj" scale="0.01 0.01 0.01"/>
    </asset>

    <worldbody>
	    <!-- <light pos=".4 -.4 .3" dir="-2 2 -1.5" diffuse=".6 .6 .6"/>
    	<light pos="-.2 -.4 .3" dir="1 2 -1.5" diffuse=".6 .6 .6"/>
    	<geom type="plane" size="5 5 .01" rgba="1 1 1 1" material="floor"/> -->
        <body name="base" pos="0 0 1.1">
            <!-- <inertial pos="-0.0508888 0.000109183 -0.0455794" quat="0.706855 0.707166 0.0123661 -0.0109307" mass="1.45117" diaginertia="0.0149302 0.0127972 0.00640923"/>
            <freejoint/> -->
            <body name="pelvis" pos="0 0 0">
                <inertial pos="-0.0002 4e-05 -0.04522" quat="0.498303 0.499454 -0.500496 0.501741" mass="5.39" diaginertia="0.0490211 0.0445821 0.00824619" />
                <geom type="mesh" group="1" density="0" rgba="0.1 0.1 0.1 1" mesh="pelvis" />
                <geom type="mesh" group="1" density="0" rgba="0.1 0.1 0.1 0" mesh="pelvis" contype="1" conaffinity="1"/>
                <geom size="0.05" rgba="0.1 0.1 0.1 1" />
                <!-- <geom type="mesh" rgba="0.1 0.1 0.1 1" mesh="pelvis"/> -->

                <body name="lower_body">
                    <!-- Left leg -->
                    <body name="left_hip_yaw_link" pos="0 0.0875 -0.1742">
                        <inertial pos="-0.04923 0.0001 0.0072" quat="0.69699 0.219193 0.233287 0.641667" mass="2.244" diaginertia="0.00304494 0.00296885 0.00189201" />
                        <joint name="left_hip_yaw_joint" pos="0 0 0" axis="0 0 1" limited="true" range="-0.43 0.43" />
                        <geom type="mesh"   group="1" rgba="0.1 0.1 0.1 1" mesh="left_hip_yaw_link" />
                        <geom type="mesh"   group="1" rgba="0.1 0.1 0.1 0" mesh="left_hip_yaw_link" contype="1" conaffinity="1"/>
                        <geom size="0.01 0.01" pos="0.02 0 0" quat="0.707107 0 0.707107 0" type="cylinder" rgba="0.1 0.1 0.1 1" />
                        <body name="left_hip_roll_link" pos="0.039468 0 0">
                            <inertial pos="-0.0058 -0.00319 -9e-05" quat="0.0438242 0.70721 -0.0729075 0.701867" mass="2.232" diaginertia="0.00243264 0.00225325 0.00205492" />
                            <joint name="left_hip_roll_joint" pos="0 0 0" axis="1 0 0" limited="true" range="-0.43 0.43" />
                            <geom type="mesh"   group="1" rgba="0.1 0.1 0.1 1" mesh="left_hip_roll_link" />
                            <geom type="mesh"   group="1" rgba="0.1 0.1 0.1 0" mesh="left_hip_roll_link" contype="1" conaffinity="1"/>
                            <geom size="0.02 0.005" pos="0 0.06 0" quat="0.707107 0.707107 0 0" type="cylinder" rgba="0.1 0.1 0.1 1" />
                            <body name="left_hip_pitch_link" pos="0 0.11536 0">
                                <inertial pos="0.00746 -0.02346 -0.08193" quat="0.979828 0.0513522 -0.0169854 -0.192382" mass="4.152" diaginertia="0.0829503 0.0821457 0.00510909" />
                                <joint name="left_hip_pitch_joint" pos="0 0 0" axis="0 1 0" limited="true" range="-3.14 2.53" />
                                <geom type="mesh"   group="1" rgba="0.1 0.1 0.1 1" mesh="left_hip_pitch_link" />
                                <geom type="mesh"   group="1" rgba="0.1 0.1 0.1 0" mesh="left_hip_pitch_link" contype="1" conaffinity="1"/>
                                <geom size="0.05 0.1" pos="0 0 -0.2" type="cylinder" rgba="0.1 0.1 0.1 1" />
                                <body name="left_knee_link" pos="0 0 -0.4">
                                    <inertial pos="0.000923 -0.00042 -0.183981" quat="0.928174 0.00315799 0.00730448 0.37206" mass="3.768" diaginertia="0.0336133 0.0334995 0.00470388" />
                                    <joint name="left_knee_joint" pos="0 0 0" axis="0 1 0" limited="true" range="-0.26 2.05" />
                                    <geom type="mesh"   group="1" rgba="0.1 0.1 0.1 1" mesh="left_knee_link" />
                                    <geom type="mesh"   group="1" rgba="0.1 0.1 0.1 0" mesh="left_knee_link" contype="1" conaffinity="1"/>
                                    <geom size="0.05 0.1" pos="0 0 -0.2" type="cylinder" rgba="0.1 0.1 0.1 1" />
                                    <body name="left_ankle_pitch_link" pos="0 0 -0.4">
                                        <inertial pos="-0.000294 0 -0.010794" quat="0.999984 0 -0.00574445 0" mass="0.102" diaginertia="2.39454e-05 2.1837e-05 1.34126e-05" />
                                        <joint name="left_ankle_pitch_joint" pos="0 0 0" axis="0 1 0" limited="true" range="-0.897334 0.523598" />
                                        <geom type="mesh"   group="1" rgba="0.1 0.1 0.1 1" mesh="left_ankle_pitch_link" />
                                        <geom type="mesh"   group="1" rgba="0.1 0.1 0.1 0" mesh="left_ankle_pitch_link" contype="1" conaffinity="1"/>
                                        <geom type="mesh" rgba="0.1 0.1 0.1 1" mesh="left_ankle_pitch_link" />
                                        <body name="left_ankle_roll_link" pos="0 0 -0.02">
                                            <inertial pos="0.033731 0.000501 -0.018756" quat="-0.00440552 0.72363 -0.00249978 0.69017" mass="1.768" diaginertia="0.0128811 0.0119853 0.00194229" />
                                            <joint name="left_ankle_roll_joint" pos="0 0 0" axis="1 0 0" limited="true" range="-0.261799 0.261799" />
                                            <geom type="mesh"   group="1" rgba="0.1 0.1 0.1 1" mesh="left_ankle_roll_link" />
                                            <geom type="mesh"   group="1" rgba="0.1 0.1 0.1 0" mesh="left_ankle_roll_link" contype="1" conaffinity="1"/>
                                            <geom type="mesh" rgba="0.1 0.1 0.1 1" mesh="left_ankle_roll_link" />
                                        </body>
                                    </body>
                                </body>
                            </body>
                        </body>
                    </body>
                    <!-- End of left leg -->
                    <!-- Right leg -->
                    <body name="right_hip_yaw_link" pos="0 -0.0875 -0.1742">
                        <inertial pos="-0.04923 -0.0001 0.0072" quat="0.641667 0.233287 0.219193 0.69699" mass="2.244" diaginertia="0.00304494 0.00296885 0.00189201" />
                        <joint name="right_hip_yaw_joint" pos="0 0 0" axis="0 0 1" limited="true" range="-0.43 0.43" />
                        <geom type="mesh"   group="1" rgba="0.1 0.1 0.1 1" mesh="right_hip_yaw_link" />
                        <geom type="mesh"   group="1" rgba="0.1 0.1 0.1 0" mesh="right_hip_yaw_link" contype="1" conaffinity="1"/>
                        <geom size="0.01 0.01" pos="0.02 0 0" quat="0.707107 0 0.707107 0" type="cylinder" rgba="0.1 0.1 0.1 1" />
                        <body name="right_hip_roll_link" pos="0.039468 0 0">
                            <inertial pos="-0.0058 0.00319 -9e-05" quat="-0.0438242 0.70721 0.0729075 0.701867" mass="2.232" diaginertia="0.00243264 0.00225325 0.00205492" />
                            <joint name="right_hip_roll_joint" pos="0 0 0" axis="1 0 0" limited="true" range="-0.43 0.43" />
                            <geom type="mesh"   group="1" rgba="0.1 0.1 0.1 1" mesh="right_hip_roll_link" />
                            <geom type="mesh"   group="1" rgba="0.1 0.1 0.1 0" mesh="right_hip_roll_link" contype="1" conaffinity="1"/>
                            <geom size="0.02 0.005" pos="0 -0.06 0" quat="0.707107 0.707107 0 0" type="cylinder" rgba="0.1 0.1 0.1 1" />
                            <body name="right_hip_pitch_link" pos="0 -0.11536 0">
                                <inertial pos="0.00746 0.02346 -0.08193" quat="0.979828 -0.0513522 -0.0169854 0.192382" mass="4.152" diaginertia="0.0829503 0.0821457 0.00510909" />
                                <joint name="right_hip_pitch_joint" pos="0 0 0" axis="0 1 0" limited="true" range="-3.14 2.53" />
                                <geom type="mesh"   group="1" rgba="0.1 0.1 0.1 1" mesh="right_hip_pitch_link" />
                                <geom type="mesh"   group="1" rgba="0.1 0.1 0.1 0" mesh="right_hip_pitch_link" contype="1" conaffinity="1"/>
                                <geom size="0.05 0.1" pos="0 0 -0.2" type="cylinder" rgba="0.1 0.1 0.1 1" />
                                <body name="right_knee_link" pos="0 0 -0.4">
                                    <inertial pos="0.000923 0.00042 -0.183981" quat="0.928174 -0.00315799 0.00730448 -0.37206" mass="3.768" diaginertia="0.0336133 0.0334995 0.00470388" />
                                    <joint name="right_knee_joint" pos="0 0 0" axis="0 1 0" limited="true" range="-0.26 2.05" />
                                    <geom type="mesh"   group="1" rgba="0.1 0.1 0.1 1" mesh="right_knee_link" />
                                    <geom type="mesh"   group="1" rgba="0.1 0.1 0.1 0" mesh="right_knee_link" contype="1" conaffinity="1"/>
                                    <geom size="0.05 0.1" pos="0 0 -0.2" type="cylinder" rgba="0.1 0.1 0.1 1" />
                                    <body name="right_ankle_pitch_link" pos="0 0 -0.4">
                                        <inertial pos="-0.000294 0 -0.010794" quat="0.999984 0 -0.00574445 0" mass="0.102" diaginertia="2.39454e-05 2.1837e-05 1.34126e-05" />
                                        <joint name="right_ankle_pitch_joint" pos="0 0 0" axis="0 1 0" limited="true" range="-0.897334 0.523598" />
                                        <geom type="mesh"   group="1" rgba="0.1 0.1 0.1 1" mesh="right_ankle_pitch_link" />
                                        <geom type="mesh"   group="1" rgba="0.1 0.1 0.1 0" mesh="right_ankle_pitch_link" contype="1" conaffinity="1"/>
                                        <geom type="mesh" rgba="0.1 0.1 0.1 1" mesh="right_ankle_pitch_link" />
                                        <body name="right_ankle_roll_link" pos="0 0 -0.02">
                                            <inertial pos="0.033731 -0.000501 -0.018756" quat="0.00440552 0.72363 0.00249978 0.69017" mass="1.768" diaginertia="0.0128811 0.0119853 0.00194229" />
                                            <joint name="right_ankle_roll_joint" pos="0 0 0" axis="1 0 0" limited="true" range="-0.261799 0.261799" />
                                            <geom type="mesh"   group="1" rgba="0.1 0.1 0.1 1" mesh="right_ankle_roll_link" />
                                            <geom type="mesh"   group="1" rgba="0.1 0.1 0.1 0" mesh="right_ankle_roll_link" contype="1" conaffinity="1"/>
                                            <geom type="mesh" rgba="0.1 0.1 0.1 1" mesh="right_ankle_roll_link" />
                                        </body>
                                    </body>
                                </body>
                            </body>
                        </body>
                    </body>
                    <!-- End of right leg -->
                </body>


                <body name="torso_link" >
                    <inertial pos="0.000489 0.002797 0.20484" quat="0.999989 -0.00130808 -0.00282289 -0.00349105" mass="17.789" diaginertia="0.487315 0.409628 0.127837" />
                    <joint name="torso_joint" pos="0 0 0" axis="0 0 1" range="-2.35 2.35" damping="100"/>
                    <geom type="mesh"   group="1" density="0" rgba="0.1 0.1 0.1 0" mesh="torso_link" contype="1" conaffinity="1"/>
                    <geom type="mesh"   group="1" density="0" rgba="0.1 0.1 0.1 1" mesh="torso_link" />
                    <geom size="0.04 0.08 0.05" pos="0 0 0.15" type="box" rgba="0.1 0.1 0.1 1" />
                    <geom type="mesh"   group="1" density="0" rgba="1 1 1 1" mesh="logo_link" />
                    <!-- Left arm -->
                    <body name="left_shoulder_pitch_link" pos="0.0055 0.15535 0.42999" quat="0.976296 0.216438 0 0">
                        <inertial pos="0.005045 0.053657 -0.015715" quat="0.814858 0.579236 -0.0201072 -0.00936488" mass="1.033" diaginertia="0.00129936 0.000987113 0.000858198" />
                        <joint name="left_shoulder_pitch_joint" pos="0 0 0" axis="0 1 0" limited="true" range="-2.44 1.44" />
                        <geom type="mesh"   group="1" rgba="0.1 0.1 0.1 1" mesh="left_shoulder_pitch_link" />
                        <geom type="mesh"   group="1" rgba="0.1 0.1 0.1 0" mesh="left_shoulder_pitch_link" contype="1" conaffinity="1"/>
                        <geom size="0.03 0.02" pos="0 -0.05 0" quat="0.707107 0.707107 0 0" type="cylinder" rgba="0.1 0.1 0.1 1" />
                        <body name="left_shoulder_roll_link" pos="-0.0055 0.0565 -0.0165" quat="0.976296 -0.216438 0 0">
                            <inertial pos="0.000679 0.00115 -0.094076" quat="0.732491 0.00917179 0.0766656 0.676384" mass="0.793" diaginertia="0.00170388 0.00158256 0.00100336" />
                            <joint name="left_shoulder_roll_joint" pos="0 0 0" axis="1 0 0" limited="true" range="-0.17 3.11" />
                            <geom type="mesh"   group="1" rgba="0.1 0.1 0.1 1" mesh="left_shoulder_roll_link" />
                            <geom type="mesh"   group="1" rgba="0.1 0.1 0.1 0" mesh="left_shoulder_roll_link" contype="1" conaffinity="1"/>
                            <geom size="0.04 0.005" pos="0 0 -0.04" type="cylinder" rgba="0.1 0.1 0.1 1" />
                            <body name="left_shoulder_yaw_link" pos="0 0 -0.1343">
                                <inertial pos="0.01365 0.002767 -0.16266" quat="0.703042 -0.0331229 -0.0473362 0.708798" mass="0.839" diaginertia="0.00408038 0.00370367 0.000622687" />
                                <joint name="left_shoulder_yaw_joint" pos="0 0 0" axis="0 0 1" limited="true" range="-1.3 1.3" />
                                <geom type="mesh"   group="1" rgba="0.1 0.1 0.1 1" mesh="left_shoulder_yaw_link" />
                                <geom type="mesh"   group="1" rgba="0.1 0.1 0.1 0" mesh="left_shoulder_yaw_link" contype="1" conaffinity="1"/>
                                <geom size="0.04 0.005" pos="0 0 -0.11" type="cylinder" rgba="0.1 0.1 0.1 1" />
                                <body name="left_elbow_pitch_link" pos="0.0185 0 -0.198">
                                    <inertial pos="0.075854 0.0002 -0.013485" quat="-0.019258 0.75458 -0.00746222 0.655882" mass="0.676" diaginertia="0.000918659 0.000891047 0.000302417" />
                                    <joint name="left_elbow_pitch_joint" pos="0 0 0" axis="0 1 0" limited="true" range="-1.25 1.57" />
                                    <geom type="mesh"   group="1" rgba="0.1 0.1 0.1 1" mesh="left_elbow_pitch_link" />
                                    <geom type="mesh"   group="1" rgba="0.1 0.1 0.1 0" mesh="left_elbow_pitch_link" contype="1" conaffinity="1"/>
                                    <geom type="mesh" rgba="0.1 0.1 0.1 1" mesh="left_elbow_pitch_link" />
                                    <body name="left_elbow_roll_link" pos="0.121 0 -0.015">
                                        <inertial pos="0.035281 -0.00232 0.000337" quat="0.334998 0.622198 -0.240131 0.66557" mass="0.683" diaginertia="0.00034681 0.000328248 0.000294628" />
                                        <joint name="left_elbow_roll_joint" pos="0 0 0" axis="1 0 0" limited="true" range="-1.57 1.57" />
                                        <geom type="mesh"   group="1" rgba="0.1 0.1 0.1 1" mesh="left_elbow_roll_link" />
                                        <geom type="mesh"   group="1" rgba="0.1 0.1 0.1 0" mesh="left_elbow_roll_link" contype="1" conaffinity="1"/>
                                        <geom type="mesh" rgba="0.1 0.1 0.1 1" mesh="left_elbow_roll_link" />
                                        <body name="left_wrist_pitch_link" pos="0.085 0 0">
                                            <inertial pos="0.020395 3.6e-05 -0.002973" quat="0.915893 -0.228405 -0.327262 -0.0432527" mass="0.484" diaginertia="7.25675e-05 7.00325e-05 6.9381e-05" />
                                            <joint name="left_wrist_pitch_joint" pos="0 0 0" axis="0 1 0" limited="true" range="-0.471 0.349" />
                                            <geom type="mesh"   group="1" rgba="0.1 0.1 0.1 1" mesh="left_wrist_pitch_link" />
                                            <geom type="mesh"   group="1" rgba="0.1 0.1 0.1 0" mesh="left_wrist_pitch_link" contype="1" conaffinity="1"/>
                                            <geom type="mesh" rgba="0.1 0.1 0.1 1" mesh="left_wrist_pitch_link" />
                                            <body name="left_wrist_yaw_link" pos="0.02 0 0">
                                                <inertial pos="0.0736357 -0.00158637 -0.00120374" quat="0.506304 0.505255 0.50628 0.48172" mass="0.22743" diaginertia="0.000505 0.00043225 0.000157919" />
                                                <joint name="left_wrist_yaw_joint" pos="0 0 0" axis="0 0 1" limited="true" range="-1.012 1.012" />
                                                <geom type="mesh"   group="1" rgba="0.1 0.1 0.1 1" mesh="wrist_yaw_link" />
                                                <geom type="mesh"   group="1" rgba="0.1 0.1 0.1 0" mesh="wrist_yaw_link" contype="1" conaffinity="1"/>
                                                <geom pos="0.0365 0 0" quat="0.707107 0 0 0.707107" type="mesh"   group="1" rgba="0.1 0.1 0.1 1" mesh="L_hand_base_link" />
                                                <geom pos="0.0365 0 0" quat="0.707107 0 0 0.707107" type="mesh" rgba="0.1 0.1 0.1 1" mesh="L_hand_base_link" />
                                                <geom pos="0.0365 0 0" quat="0.707107 0 0 0.707107" type="mesh"  group="1" rgba="0.1 0.1 0.1 0" mesh="L_hand_base_link" contype="1" conaffinity="1"/>
                                                <!-- Changed the order of the fingers to match mujoco format (different from urdf) -->
                                                <body name="L_index_proximal" pos="0.17303 0.00028533 0.032268" quat="0.706999 -0.0123409 -0.0123409 0.706999">
                                                    <inertial pos="0.0012971 -0.011934 -0.0059998" quat="0.489677 0.510115 -0.489692 0.510099" mass="0.0042405" diaginertia="6.9402e-07 6.62904e-07 2.10916e-07" />
                                                    <joint name="L_index_proximal_joint" pos="0 0 0" axis="0 0 -1" limited="true" range="0 1.7" />
                                                    <geom type="mesh"   group="1" rgba="0.1 0.1 0.1 1" mesh="Link15_L" />
                                                    <geom type="mesh"   group="1" rgba="0.1 0.1 0.1 0" mesh="Link15_L" contype="1" conaffinity="1"/>
                                                    <geom type="mesh" rgba="0.1 0.1 0.1 1" mesh="Link15_L" />
                                                    <body name="L_index_intermediate" pos="-0.0024229 -0.032041 -0.001">
                                                        <inertial pos="0.0021753 -0.019567 -0.005" quat="0.528694 0.469555 -0.528694 0.469555" mass="0.0045682" diaginertia="7.8176e-07 7.72427e-07 8.47209e-08" />
                                                        <joint name="L_index_intermediate_joint" pos="0 0 0" axis="0 0 -1" limited="true" range="0 1.7" />
                                                        <geom type="mesh"   group="1" rgba="0.1 0.1 0.1 1" mesh="Link16_L" />
                                                        <geom type="mesh"   group="1" rgba="0.1 0.1 0.1 0" mesh="Link16_L" contype="1" conaffinity="1"/>
                                                        <geom type="mesh" rgba="0.1 0.1 0.1 1" mesh="Link16_L" />
                                                    </body>
                                                </body>
                                                <body name="L_middle_proximal" pos="0.1736 0.00028533 0.01295" quat="0.707107 0 0 0.707107">
                                                    <inertial pos="0.0012971 -0.011934 -0.0059999" quat="0.489677 0.510115 -0.489692 0.510099" mass="0.0042405" diaginertia="6.9402e-07 6.62904e-07 2.10916e-07" />
                                                    <joint name="L_middle_proximal_joint" pos="0 0 0" axis="0 0 -1" limited="true" range="0 1.7" />
                                                    <geom type="mesh"   group="1" rgba="0.1 0.1 0.1 1" mesh="Link17_L" />
                                                    <geom type="mesh"   group="1" rgba="0.1 0.1 0.1 0" mesh="Link17_L" contype="1" conaffinity="1"/>
                                                    <geom type="mesh" rgba="0.1 0.1 0.1 1" mesh="Link17_L" />
                                                    <body name="L_middle_intermediate" pos="-0.0024229 -0.032041 -0.001">
                                                        <inertial pos="0.001921 -0.020796 -0.0049999" quat="0.531603 0.466115 -0.531728 0.466262" mass="0.0050397" diaginertia="9.8385e-07 9.73288e-07 9.14016e-08" />
                                                        <joint name="L_middle_intermediate_joint" pos="0 0 0" axis="0 0 -1" limited="true" range="0 1.7" />
                                                        <geom type="mesh"   group="1" rgba="0.1 0.1 0.1 1" mesh="Link18_L" />
                                                        <geom type="mesh"   group="1" rgba="0.1 0.1 0.1 0" mesh="Link18_L" contype="1" conaffinity="1"/>
                                                        <geom type="mesh" rgba="0.1 0.1 0.1 1" mesh="Link18_L" />
                                                    </body>
                                                </body>
                                                <body name="L_pinky_proximal" pos="0.17221 0.00028533 -0.025488" quat="0.706138 0.0370072 0.0370072 0.706138">
                                                    <inertial pos="0.0012971 -0.011934 -0.0059999" quat="0.489677 0.510114 -0.489692 0.510099" mass="0.0042405" diaginertia="6.9402e-07 6.62904e-07 2.10916e-07" />
                                                    <joint name="L_pinky_proximal_joint" pos="0 0 0" axis="0 0 -1" limited="true" range="0 1.7" />
                                                    <geom type="mesh"   group="1" rgba="0.1 0.1 0.1 1" mesh="Link21_L" />
                                                    <geom type="mesh"   group="1" rgba="0.1 0.1 0.1 0" mesh="Link21_L" contype="1" conaffinity="1"/>
                                                    <geom type="mesh" rgba="0.1 0.1 0.1 1" mesh="Link21_L" />
                                                    <body name="L_pinky_intermediate" pos="-0.0024229 -0.032041 -0.001">
                                                        <inertial pos="0.0024788 -0.016208 -0.0050001" quat="0.526797 0.471683 -0.526793 0.471687" mass="0.0036036" diaginertia="4.4881e-07 4.43809e-07 6.5736e-08" />
                                                        <joint name="L_pinky_intermediate_joint" pos="0 0 0" axis="0 0 -1" limited="true" range="0 1.7" />
                                                        <geom type="mesh"   group="1" rgba="0.1 0.1 0.1 1" mesh="Link22_L" />
                                                        <geom type="mesh"   group="1" rgba="0.1 0.1 0.1 0" mesh="Link22_L" contype="1" conaffinity="1"/>
                                                        <geom type="mesh" rgba="0.1 0.1 0.1 1" mesh="Link22_L" />
                                                    </body>
                                                </body>
                                                <body name="L_ring_proximal" pos="0.17341 0.00028533 -0.0062872" quat="0.706864 0.0185099 0.0185099 0.706864">
                                                    <inertial pos="0.0012971 -0.011934 -0.0059999" quat="0.489677 0.510114 -0.489692 0.510099" mass="0.0042405" diaginertia="6.9402e-07 6.62904e-07 2.10916e-07" />
                                                    <joint name="L_ring_proximal_joint" pos="0 0 0" axis="0 0 -1" limited="true" range="0 1.7" />
                                                    <geom type="mesh"   group="1" rgba="0.1 0.1 0.1 1" mesh="Link19_L" />
                                                    <geom type="mesh"   group="1" rgba="0.1 0.1 0.1 0" mesh="Link19_L" contype="1" conaffinity="1"/>
                                                    <geom type="mesh" rgba="0.1 0.1 0.1 1" mesh="Link19_L" />
                                                    <body name="L_ring_intermediate" pos="-0.0024229 -0.032041 -0.001">
                                                        <inertial pos="0.0021753 -0.019567 -0.005" quat="0.528694 0.469556 -0.528694 0.469556" mass="0.0045682" diaginertia="7.8176e-07 7.72437e-07 8.47208e-08" />
                                                        <joint name="L_ring_intermediate_joint" pos="0 0 0" axis="0 0 -1" limited="true" range="0 1.7" />
                                                        <geom type="mesh"   group="1" rgba="0.1 0.1 0.1 1" mesh="Link20_L" />
                                                        <geom type="mesh"   group="1" rgba="0.1 0.1 0.1 0" mesh="Link20_L" contype="1" conaffinity="1"/>
                                                        <geom type="mesh" rgba="0.1 0.1 0.1 1" mesh="Link20_L" />
                                                    </body>
                                                </body>
                                                <body name="L_thumb_proximal_base" pos="0.1056 -0.01696 0.02045" quat="-2.59735e-06 0.707107 0 0.707107">
                                                    <inertial pos="0.0048817 0.00038782 -0.00722" quat="0.445981 0.352284 0.495833 0.656617" mass="0.0018869" diaginertia="8.66031e-08 6.87331e-08 4.94199e-08" />
                                                    <joint name="L_thumb_proximal_yaw_joint" pos="0 0 0" axis="0 0 1" limited="true" range="-0.1 1.3" />
                                                    <geom type="mesh"   group="1" rgba="0.1 0.1 0.1 1" mesh="Link11_L" />
                                                    <geom type="mesh"   group="1" rgba="0.1 0.1 0.1 0" mesh="Link11_L" contype="1" conaffinity="1"/>
                                                    <geom type="mesh" rgba="0.1 0.1 0.1 1" mesh="Link11_L" />
                                                    <body name="L_thumb_proximal" pos="0.0099867 0.0098242 -0.0089" quat="0.704571 -0.704573 -0.0598169 0.0598167">
                                                        <inertial pos="0.021936 -0.01279 -0.0080386" quat="0.25452 0.660687 -0.251949 0.659723" mass="0.0066101" diaginertia="2.78701e-06 2.44024e-06 8.6466e-07" />
                                                        <joint name="L_thumb_proximal_pitch_joint" pos="0 0 0" axis="0 0 -1" limited="true" range="0 0.5" />
                                                        <geom type="mesh"   group="1" rgba="0.1 0.1 0.1 1" mesh="Link12_L" />
                                                        <geom type="mesh"   group="1" rgba="0.1 0.1 0.1 0" mesh="Link12_L" contype="1" conaffinity="1"/>
                                                        <geom type="mesh" rgba="0.1 0.1 0.1 1" mesh="Link12_L" />
                                                        <body name="L_thumb_intermediate" pos="0.04407 -0.034553 -0.0008">
                                                            <inertial pos="0.0095531 0.0016282 -0.0072002" quat="0.30738 0.636732 -0.307526 0.636803" mass="0.0037844" diaginertia="4.6532e-07 4.48114e-07 2.45646e-07" />
                                                            <joint name="L_thumb_intermediate_joint" pos="0 0 0" axis="0 0 -1" limited="true" range="0 0.8" />
                                                            <geom type="mesh"   group="1" rgba="0.1 0.1 0.1 1" mesh="Link13_L" />
                                                            <geom type="mesh"   group="1" rgba="0.1 0.1 0.1 0" mesh="Link13_L" contype="1" conaffinity="1"/>
                                                            <geom type="mesh" rgba="0.1 0.1 0.1 1" mesh="Link13_L" />
                                                            <body name="L_thumb_distal" pos="0.020248 -0.010156 -0.0012">
                                                                <inertial pos="0.0092888 -0.004953 -0.0060033" quat="0.266264 0.65596 -0.262836 0.655544" mass="0.003344" diaginertia="2.0026e-07 1.95246e-07 8.1594e-08" />
                                                                <joint name="L_thumb_distal_joint" pos="0 0 0" axis="0 0 -1" limited="true" range="0 1.2" />
                                                                <geom type="mesh"   group="1" rgba="0.1 0.1 0.1 1" mesh="Link14_L" />
                                                                <geom type="mesh"   group="1" rgba="0.1 0.1 0.1 0" mesh="Link14_L" contype="1" conaffinity="1"/>
                                                                <geom type="mesh" rgba="0.1 0.1 0.1 1" mesh="Link14_L" />
                                                            </body>
                                                        </body>
                                                    </body>
                                                </body>
                                            </body>
                                        </body>
                                    </body>
                                </body>
                            </body>
                        </body>
                    </body>
                    <!-- End of left arm -->
                    <!-- Right arm -->
                    <body name="right_shoulder_pitch_link" pos="0.0055 -0.15535 0.42999" quat="0.976296 -0.216438 0 0">
                        <inertial pos="0.005045 -0.053657 -0.015715" quat="0.579236 0.814858 0.00936488 0.0201072" mass="1.033" diaginertia="0.00129936 0.000987113 0.000858198"/>
                        <joint name="right_shoulder_pitch_joint" pos="0 0 0" axis="0 1 0" limited="true" range="-2.44 1.44" />
                        <geom type="mesh"   group="1" rgba="0.1 0.1 0.1 1" mesh="right_shoulder_pitch_link" />
                        <geom type="mesh"   group="1" rgba="0.1 0.1 0.1 0" mesh="right_shoulder_pitch_link" contype="1" conaffinity="1"/>
                        <geom size="0.03 0.02" pos="0 0.05 0" quat="0.707107 -0.707107 0 0" type="cylinder" rgba="0.1 0.1 0.1 1" />
                        <body name="right_shoulder_roll_link" pos="-0.0055 -0.0565 -0.0165" quat="0.976296 0.216438 0 0">
                            <inertial pos="0.000679 -0.00115 -0.094076" quat="0.676384 0.0766656 0.00917179 0.732491" mass="0.793" diaginertia="0.00170388 0.00158256 0.00100336"/>
                            <joint name="right_shoulder_roll_joint" pos="0 0 0" axis="1 0 0" limited="true" range="-3.11 0.17" />
                            <geom type="mesh"   group="1" rgba="0.1 0.1 0.1 1" mesh="right_shoulder_roll_link" />
                            <geom type="mesh"   group="1" rgba="0.1 0.1 0.1 0" mesh="right_shoulder_roll_link" contype="1" conaffinity="1"/>
                            <geom size="0.04 0.005" pos="0 0 -0.04" type="cylinder" rgba="0.1 0.1 0.1 1" />
                            <body name="right_shoulder_yaw_link" pos="0 0 -0.1343">
                                <inertial pos="0.01365 -0.002767 -0.16266" quat="0.708798 -0.0473362 -0.0331229 0.703042" mass="0.839" diaginertia="0.00408038 0.00370367 0.000622687"/>
                                <joint name="right_shoulder_yaw_joint" pos="0 0 0" axis="0 0 1" limited="true" range="-1.3 1.3" />
                                <geom type="mesh"   group="1" rgba="0.1 0.1 0.1 1" mesh="right_shoulder_yaw_link" />
                                <geom type="mesh"   group="1" rgba="0.1 0.1 0.1 0" mesh="right_shoulder_yaw_link" contype="1" conaffinity="1"/>
                                <geom size="0.04 0.005" pos="0 0 -0.11" type="cylinder" rgba="0.1 0.1 0.1 1" />
                                <body name="right_elbow_pitch_link" pos="0.0185 0 -0.198">
                                    <inertial pos="0.075854 0.0002 -0.013485" quat="-0.019258 0.75458 -0.00746222 0.655882" mass="0.676" diaginertia="0.000918659 0.000891047 0.000302417" />
                                    <joint name="right_elbow_pitch_joint" pos="0 0 0" axis="0 1 0" limited="true" range="-1.25 1.57" />
                                    <geom type="mesh"   group="1" rgba="0.1 0.1 0.1 1" mesh="right_elbow_pitch_link" />
                                    <geom type="mesh"   group="1" rgba="0.1 0.1 0.1 0" mesh="right_elbow_pitch_link" contype="1" conaffinity="1"/>
                                    <geom type="mesh" rgba="0.1 0.1 0.1 1" mesh="right_elbow_pitch_link" />
                                    <body name="right_elbow_roll_link" pos="0.121 0 -0.015">
                                        <inertial pos="0.035281 -0.00232 0.000337" quat="0.334998 0.622198 -0.240131 0.66557" mass="0.683" diaginertia="0.00034681 0.000328248 0.000294628" />
                                        <joint name="right_elbow_roll_joint" pos="0 0 0" axis="1 0 0" limited="true" range="-1.57 1.57" />
                                        <geom type="mesh"   group="1" rgba="0.1 0.1 0.1 1" mesh="right_elbow_roll_link" />
                                        <geom type="mesh"   group="1" rgba="0.1 0.1 0.1 0" mesh="right_elbow_roll_link" contype="1" conaffinity="1"/>
                                        <geom type="mesh" rgba="0.1 0.1 0.1 1" mesh="right_elbow_roll_link" />
                                        <body name="right_wrist_pitch_link" pos="0.085 0 0">
                                            <inertial pos="0.020395 3.6e-05 -0.002973" quat="0.915893 -0.228405 -0.327262 -0.0432527" mass="0.484" diaginertia="7.25675e-05 7.00325e-05 6.9381e-05" />
                                            <joint name="right_wrist_pitch_joint" pos="0 0 0" axis="0 1 0" limited="true" range="-0.471 0.349" />
                                            <geom type="mesh"   group="1" rgba="0.1 0.1 0.1 1" mesh="right_wrist_pitch_link" />
                                            <geom type="mesh"   group="1" rgba="0.1 0.1 0.1 0" mesh="right_wrist_pitch_link" contype="1" conaffinity="1"/>
                                            <geom type="mesh" rgba="0.1 0.1 0.1 1" mesh="right_wrist_pitch_link" />
                                            <body name="right_wrist_yaw_link" pos="0.02 0 0">
                                                <inertial pos="0.0736357 0.00157107 -0.00121872" quat="0.481705 0.506379 0.505251 0.506223" mass="0.22743" diaginertia="0.000504412 0.000431678 0.000157916" />
                                                <joint name="right_wrist_yaw_joint" pos="0 0 0" axis="0 0 1" limited="true" range="-1.012 1.012" />
                                                <geom type="mesh"   group="1" rgba="0.1 0.1 0.1 1" mesh="wrist_yaw_link" />
                                                <geom type="mesh"   group="1" rgba="0.1 0.1 0.1 0" mesh="wrist_yaw_link" contype="1" conaffinity="1"/>
                                                <geom type="mesh" rgba="0.1 0.1 0.1 1" mesh="wrist_yaw_link" />
                                                <geom pos="0.0365 0 0" quat="0 0.707107 -0.707107 0" type="mesh"   group="1" rgba="0.1 0.1 0.1 1" mesh="R_hand_base_link" />
                                                <geom pos="0.0365 0 0" quat="0 0.707107 -0.707107 0" type="mesh"   group="1" rgba="0.1 0.1 0.1 0" mesh="R_hand_base_link" contype="1" conaffinity="1"/>
                                                <geom pos="0.0365 0 0" quat="0 0.707107 -0.707107 0" type="mesh" rgba="0.1 0.1 0.1 1" mesh="R_hand_base_link" />
                                                <!-- Changed the order of the fingers to match mujoco format (different from urdf) -->
                                                <body name="R_index_proximal" pos="0.17303 -0.00028533 0.032268" quat="0.706999 0.0123358 -0.0123358 -0.706999">
                                                    <inertial pos="0.0012259 0.011942 -0.0060001" quat="0.50867 0.49121 -0.508643 0.491172" mass="0.0042403" diaginertia="6.9398e-07 6.62871e-07 2.10909e-07" />
                                                    <joint name="R_index_proximal_joint" pos="0 0 0" axis="0 0 1" limited="true" range="0 1.7" />
                                                    <geom type="mesh"   group="1" rgba="0.1 0.1 0.1 1" mesh="Link15_R" />
                                                    <geom type="mesh"   group="1" rgba="0.1 0.1 0.1 0" mesh="Link15_R" contype="1" conaffinity="1"/>
                                                    <geom type="mesh" rgba="0.1 0.1 0.1 1" mesh="Link15_R" />
                                                    <body name="R_index_intermediate" pos="-0.0026138 0.032026 -0.001">
                                                        <inertial pos="0.0019697 0.019589 -0.005" quat="0.466773 0.531152 -0.466773 0.531153" mass="0.0045683" diaginertia="7.8179e-07 7.72465e-07 8.47212e-08" />
                                                        <joint name="R_index_intermediate_joint" pos="0 0 0" axis="0 0 1" limited="true" range="0 1.7" />
                                                        <geom type="mesh"   group="1" rgba="0.1 0.1 0.1 1" mesh="Link16_R" />
                                                        <geom type="mesh"   group="1" rgba="0.1 0.1 0.1 0" mesh="Link16_R" contype="1" conaffinity="1"/>
                                                        <geom type="mesh" rgba="0.1 0.1 0.1 1" mesh="Link16_R" />
                                                    </body>
                                                </body>
                                                <body name="R_middle_proximal" pos="0.1736 -0.00028533 0.01295" quat="0.707107 -2.59735e-06 2.59735e-06 -0.707107">
                                                    <inertial pos="0.001297 0.011934 -0.0060001" quat="0.510131 0.489693 -0.510105 0.489653" mass="0.0042403" diaginertia="6.9397e-07 6.62865e-07 2.10915e-07" />
                                                    <joint name="R_middle_proximal_joint" pos="0 0 0" axis="0 0 1" limited="true" range="0 1.7" />
                                                    <geom type="mesh"   group="1" rgba="0.1 0.1 0.1 1" mesh="Link17_R" />
                                                    <geom type="mesh"   group="1" rgba="0.1 0.1 0.1 0" mesh="Link17_R" contype="1" conaffinity="1"/>
                                                    <geom type="mesh" rgba="0.1 0.1 0.1 1" mesh="Link17_R" />
                                                    <body name="R_middle_intermediate" pos="-0.0024229 0.032041 -0.001">
                                                        <inertial pos="0.001921 0.020796 -0.005" quat="0.466148 0.531627 -0.466229 0.531705" mass="0.0050396" diaginertia="9.8384e-07 9.73279e-07 9.14014e-08" />
                                                        <joint name="R_middle_intermediate_joint" pos="0 0 0" axis="0 0 1" limited="true" range="0 1.7" />
                                                        <geom type="mesh"   group="1" rgba="0.1 0.1 0.1 1" mesh="Link18_R" />
                                                        <geom type="mesh"   group="1" rgba="0.1 0.1 0.1 0" mesh="Link18_R" contype="1" conaffinity="1"/>
                                                        <geom type="mesh" rgba="0.1 0.1 0.1 1" mesh="Link18_R" />
                                                    </body>
                                                </body>
                                                <body name="R_pinky_proximal" pos="0.17221 -0.00028533 -0.025488" quat="-0.706138 0.0369975 -0.0369975 0.706138">
                                                    <inertial pos="0.001297 0.011934 -0.0060001" quat="0.51013 0.489693 -0.510106 0.489653" mass="0.0042403" diaginertia="6.9397e-07 6.62865e-07 2.10915e-07" />
                                                    <joint name="R_pinky_proximal_joint" pos="0 0 0" axis="0 0 1" limited="true" range="0 1.7" />
                                                    <geom type="mesh"   group="1" rgba="0.1 0.1 0.1 1" mesh="Link21_R" />
                                                    <geom type="mesh"   group="1" rgba="0.1 0.1 0.1 0" mesh="Link21_R" contype="1" conaffinity="1"/>
                                                    <geom type="mesh" rgba="0.1 0.1 0.1 1" mesh="Link21_R" />
                                                    <body name="R_pinky_intermediate" pos="-0.0024229 0.032041 -0.001">
                                                        <inertial pos="0.0024748 0.016203 -0.0050031" quat="0.47398 0.528862 -0.469291 0.524799" mass="0.0035996" diaginertia="4.4867e-07 4.43723e-07 6.56538e-08" />
                                                        <joint name="R_pinky_intermediate_joint" pos="0 0 0" axis="0 0 1" limited="true" range="0 1.7" />
                                                        <geom type="mesh"   group="1" rgba="0.1 0.1 0.1 1" mesh="Link22_R" />
                                                        <geom type="mesh"   group="1" rgba="0.1 0.1 0.1 0" mesh="Link22_R" contype="1" conaffinity="1"/>
                                                        <geom type="mesh" rgba="0.1 0.1 0.1 1" mesh="Link22_R" />
                                                    </body>r
                                                </body>
                                                <body name="R_ring_proximal" pos="0.17341 -0.00028533 -0.0062872" quat="-0.706864 0.0185215 -0.0185215 0.706864">
                                                    <inertial pos="0.001297 0.011934 -0.0060002" quat="0.510129 0.489691 -0.510107 0.489654" mass="0.0042403" diaginertia="6.9397e-07 6.62865e-07 2.10915e-07" />
                                                    <joint name="R_ring_proximal_joint" pos="0 0 0" axis="0 0 1" limited="true" range="0 1.7" />
                                                    <geom type="mesh"   group="1" rgba="0.1 0.1 0.1 1" mesh="Link19_R" />
                                                    <geom type="mesh"   group="1" rgba="0.1 0.1 0.1 0" mesh="Link19_R" contype="1" conaffinity="1"/>
                                                    <geom type="mesh" rgba="0.1 0.1 0.1 1" mesh="Link19_R" />
                                                    <body name="R_ring_intermediate" pos="-0.0024229 0.032041 -0.001">
                                                        <inertial pos="0.0021753 0.019567 -0.005" quat="0.469554 0.528695 -0.469554 0.528695" mass="0.0045683" diaginertia="7.8177e-07 7.72448e-07 8.4722e-08" />
                                                        <joint name="R_ring_intermediate_joint" pos="0 0 0" axis="0 0 1" limited="true" range="0 1.7" />
                                                        <geom type="mesh"   group="1" rgba="0.1 0.1 0.1 1" mesh="Link20_R" />
                                                        <geom type="mesh"   group="1" rgba="0.1 0.1 0.1 0" mesh="Link20_R" contype="1" conaffinity="1"/>
                                                        <geom type="mesh" rgba="0.1 0.1 0.1 1" mesh="Link20_R" />
                                                    </body>
                                                </body>
                                                <body name="R_thumb_proximal_base" pos="0.1056 0.01696 0.02045" quat="-0.707107 -2.59735e-06 -0.707107 0">
                                                    <inertial pos="-0.0048064 0.0009382 -0.00757" quat="0.515015 0.680854 0.408023 0.323596" mass="0.0018869" diaginertia="8.66026e-08 6.8732e-08 4.94194e-08" />
                                                    <joint name="R_thumb_proximal_yaw_joint" pos="0 0 0" axis="0 0 -1" limited="true" range="-0.1 1.3" />
                                                    <geom type="mesh"   group="1" rgba="0.1 0.1 0.1 1" mesh="Link11_R" />
                                                    <geom type="mesh"   group="1" rgba="0.1 0.1 0.1 0" mesh="Link11_R" contype="1" conaffinity="1"/>
                                                    <geom type="mesh" rgba="0.1 0.1 0.1 1" mesh="Link11_R" />
                                                    <body name="R_thumb_proximal" pos="-0.0088099 0.010892 -0.00925" quat="0.0996843 0.0996847 0.700046 0.700044">
                                                        <inertial pos="0.021932 0.012785 -0.0080386" quat="-0.254474 0.660716 0.251893 0.659733" mass="0.0066075" diaginertia="2.78601e-06 2.43933e-06 8.64566e-07" />
                                                        <joint name="R_thumb_proximal_pitch_joint" pos="0 0 0" axis="0 0 1" limited="true" range="0 0.5" />
                                                        <geom type="mesh"   group="1" rgba="0.1 0.1 0.1 1" mesh="Link12_R" />
                                                        <geom type="mesh"   group="1" rgba="0.1 0.1 0.1 0" mesh="Link12_R" contype="1" conaffinity="1"/>
                                                        <geom type="mesh" rgba="0.1 0.1 0.1 1" mesh="Link12_R" />
                                                        <body name="R_thumb_intermediate" pos="0.04407 0.034553 -0.0008">
                                                            <inertial pos="0.0095544 -0.0016282 -0.0071997" quat="0.636718 0.307389 -0.636802 0.307548" mass="0.0037847" diaginertia="4.6531e-07 4.48089e-07 2.45661e-07" />
                                                            <joint name="R_thumb_intermediate_joint" pos="0 0 0" axis="0 0 1" limited="true" range="0 0.8" />
                                                            <geom type="mesh"   group="1" rgba="0.1 0.1 0.1 1" mesh="Link13_R" />
                                                            <geom type="mesh"   group="1" rgba="0.1 0.1 0.1 0" mesh="Link13_R" contype="1" conaffinity="1"/>
                                                            <geom type="mesh" rgba="0.1 0.1 0.1 1" mesh="Link13_R" />
                                                            <body name="R_thumb_distal" pos="0.020248 0.010156 -0.0012">
                                                                <inertial pos="0.0092888 0.0049529 -0.0060033" quat="-0.266294 0.655967 0.262806 0.655537" mass="0.0033441" diaginertia="2.0026e-07 1.95247e-07 8.1593e-08" />
                                                                <joint name="R_thumb_distal_joint" pos="0 0 0" axis="0 0 1" limited="true" range="0 1.2" />
                                                                <geom type="mesh"   group="1" rgba="0.1 0.1 0.1 1" mesh="Link14_R" />
                                                                <geom type="mesh"   group="1" rgba="0.1 0.1 0.1 0" mesh="Link14_R" contype="1" conaffinity="1"/>
                                                                <geom type="mesh" rgba="0.1 0.1 0.1 1" mesh="Link14_R" />
                                                            </body>
                                                        </body>
                                                    </body>
                                                </body>
                                            </body>
                                        </body>
                                    </body>
                                </body>
                            </body>
                        </body>
                    </body>
                    <!-- End of right arm -->

                </body>

            </body>
        </body>
        <!-- robot view -->
        <camera mode="fixed" name="robotview" pos="1.0 0 0.8" quat="0.653 0.271 0.271 0.653"/>
        <!-- <inertial diaginertia="0 0 0" mass="0" pos="0 0 0"/> -->
        <!-- mount attached here -->

        <!-- Add table -->
        <body name="table" pos="0.4 0 1.15" quat="1 0 0 0">
            <geom type="box" 
                  group="0"
                  size="0.165 0.165 0.05"
                  rgba="0.8 0.8 0.8 1" 
                  friction="1 0.005 0.0001" 
                  contype="1"
                  conaffinity="1"
                  condim="3" />
        </body>

        <!-- Add mug -->
        <body name="cube" pos="0.4 0 1.25" quat="1 0 0 0">
            <inertial pos="0 0 0" mass="0.2" diaginertia="0.001 0.001 0.001"/>
            <!-- <freejoint/>  Changed from <joint type="free"/> -->
            <joint type="free"/>
            <geom type="mesh" 
                  mesh="mug_visual"
                  contype="0"
                  conaffinity="0"
                  group="1"
                  rgba="1 0 0 1"/>
            <geom type="mesh"
                  mesh="mug_collision"
                  rgba="1 0 0 0"
                  contype="1"
                  conaffinity="1"/>
        </body>
    </worldbody>
    <actuator>
        <position ctrllimited="true" ctrlrange = "-0.43 0.43" forcerange="-200 200" name="left_hip_yaw_actuator" joint="left_hip_yaw_joint"/>
        <position ctrllimited="true" ctrlrange = "-0.43 0.43" forcerange="-200 200" name="left_hip_roll_actuator" joint="left_hip_roll_joint"/>
        <position ctrllimited="true" ctrlrange = "-3.14 2.53" forcerange="-200 200" name="left_hip_pitch_actuator" joint="left_hip_pitch_joint"/>
        <position ctrllimited="true" ctrlrange = "-0.26 2.05" forcerange="-300 300" name="left_knee_actuator" joint="left_knee_joint"/>
        <position ctrllimited="true" ctrlrange = "-0.89 0.52" forcerange="-40 40" name="left_ankle_pitch_actuator" joint="left_ankle_pitch_joint"/>
        <position ctrllimited="true" ctrlrange = "-0.26 0.26" forcerange="-40 40" name="left_ankle_roll_actuator" joint="left_ankle_roll_joint"/>
        <position ctrllimited="true" ctrlrange = "-0.43 0.43" forcerange="-200 200" name="right_hip_yaw_actuator" joint="right_hip_yaw_joint"/>
        <position ctrllimited="true" ctrlrange = "-0.43 0.43" forcerange="-200 200" name="right_hip_roll_actuator" joint="right_hip_roll_joint"/>
        <position ctrllimited="true" ctrlrange = "-3.14 2.53" forcerange="-200 200" name="right_hip_pitch_actuator" joint="right_hip_pitch_joint"/>
        <position ctrllimited="true" ctrlrange = "-0.26 2.05" forcerange="-300 300" name="right_knee_actuator" joint="right_knee_joint"/>
        <position ctrllimited="true" ctrlrange = "-0.89 0.52" forcerange="-40 40" name="right_ankle_pitch_actuator" joint="right_ankle_pitch_joint"/>
        <position ctrllimited="true" ctrlrange = "-0.26 0.26" forcerange="-40 40" name="right_ankle_roll_actuator" joint="right_ankle_roll_joint"/>
        
        <position ctrllimited="true" ctrlrange="-2.35 2.35" forcerange="-200 200" name="torso_actuator" joint="torso_joint"/>

        <position ctrllimited="true" ctrlrange="-2.44 1.44" forcerange="-40 40" name="left_shoulder_pitch_actuator" joint="left_shoulder_pitch_joint"/>
        <position ctrllimited="true" ctrlrange="-0.17 3.11" forcerange="-40 40" name="left_shoulder_roll_actuator" joint="left_shoulder_roll_joint"/>
        <position ctrllimited="true" ctrlrange="-1.3 1.3" forcerange="-18 18" name="left_shoulder_yaw_actuator" joint="left_shoulder_yaw_joint"/>
        <position ctrllimited="true" ctrlrange="-1.25 1.57" forcerange="-18 18" name="left_elbow_pitch_actuator" joint="left_elbow_pitch_joint"/>
        <position ctrllimited="true" ctrlrange="-1.57 1.57" forcerange="-18 18" name="left_elbow_roll_actuator" joint="left_elbow_roll_joint"/>
        <position ctrllimited="true" ctrlrange="-0.471 0.349" forcerange="-19 19" name="left_wrist_pitch_actuator" joint="left_wrist_pitch_joint"/>
        <position ctrllimited="true" ctrlrange="-1.012 1.012" forcerange="-19 19" name="left_wrist_yaw_actuator" joint="left_wrist_yaw_joint"/>
        
        <position ctrllimited="true" ctrlrange="+0.0 1.7" forcerange="-1 1" name="L_index_proximal_actuator" joint="L_index_proximal_joint"/>
        <position ctrllimited="true" ctrlrange="+0.0 1.7" forcerange="-1 1" name="L_index_intermediate_actuator" joint="L_index_intermediate_joint"/>
        <position ctrllimited="true" ctrlrange="+0.0 1.7" forcerange="-1 1" name="L_middle_proximal_actuator" joint="L_middle_proximal_joint"/>
        <position ctrllimited="true" ctrlrange="+0.0 1.7" forcerange="-1 1" name="L_middle_intermediate_actuator" joint="L_middle_intermediate_joint"/>
        <position ctrllimited="true" ctrlrange="+0.0 1.7" forcerange="-1 1" name="L_pinky_proximal_actuator" joint="L_pinky_proximal_joint"/>
        <position ctrllimited="true" ctrlrange="+0.0 1.7" forcerange="-1 1" name="L_pinky_intermediate_actuator" joint="L_pinky_intermediate_joint"/>
        <position ctrllimited="true" ctrlrange="+0.0 1.7" forcerange="-1 1" name="L_ring_proximal_actuator" joint="L_ring_proximal_joint"/>
        <position ctrllimited="true" ctrlrange="+0.0 1.7" forcerange="-1 1" name="L_ring_intermediate_actuator" joint="L_ring_intermediate_joint"/>
        <position ctrllimited="true" ctrlrange="-0.1 1.3" forcerange="-1 1" name="L_thumb_proximal_yaw_actuator" joint="L_thumb_proximal_yaw_joint"/>
        <position ctrllimited="true" ctrlrange="+0.0 0.5" forcerange="-1 1" name="L_thumb_proximal_pitch_actuator" joint="L_thumb_proximal_pitch_joint"/>
        <position ctrllimited="true" ctrlrange="+0.0 0.8" forcerange="-1 1" name="L_thumb_intermediate_actuator" joint="L_thumb_intermediate_joint"/>
        <position ctrllimited="true" ctrlrange="+0.0 1.2" forcerange="-1 1" name="L_thumb_distal_actuator" joint="L_thumb_distal_joint"/>

        <position ctrllimited="true" ctrlrange="-2.44 1.44" forcerange="-40 40" name="right_shoulder_pitch_actuator" joint="right_shoulder_pitch_joint"/>
        <position ctrllimited="true" ctrlrange="-0.17 3.11" forcerange="-40 40" name="right_shoulder_roll_actuator" joint="right_shoulder_roll_joint"/>
        <position ctrllimited="true" ctrlrange="-1.3 1.3" forcerange="-18 18" name="right_shoulder_yaw_actuator" joint="right_shoulder_yaw_joint"/>
        <position ctrllimited="true" ctrlrange="-1.25 1.57" forcerange="-18 18" name="right_elbow_pitch_actuator" joint="right_elbow_pitch_joint"/>
        <position ctrllimited="true" ctrlrange="-1.57 1.57" forcerange="-18 18" name="right_elbow_roll_actuator" joint="right_elbow_roll_joint"/>
        <position ctrllimited="true" ctrlrange="-0.471 0.349" forcerange="-19 19" name="right_wrist_pitch_actuator" joint="right_wrist_pitch_joint"/>
        <position ctrllimited="true" ctrlrange="-1.012 1.012" forcerange="-19 19" name="right_wrist_yaw_actuator" joint="right_wrist_yaw_joint"/>
        
        <position ctrllimited="true" ctrlrange="+0.0 1.7" forcerange="-1 1" name="R_index_proximal_actuator" joint="R_index_proximal_joint"/>
        <position ctrllimited="true" ctrlrange="+0.0 1.7" forcerange="-1 1" name="R_index_intermediate_actuator" joint="R_index_intermediate_joint"/>
        <position ctrllimited="true" ctrlrange="+0.0 1.7" forcerange="-1 1" name="R_middle_proximal_actuator" joint="R_middle_proximal_joint"/>
        <position ctrllimited="true" ctrlrange="+0.0 1.7" forcerange="-1 1" name="R_middle_intermediate_actuator" joint="R_middle_intermediate_joint"/>
        <position ctrllimited="true" ctrlrange="+0.0 1.7" forcerange="-1 1" name="R_pinky_proximal_actuator" joint="R_pinky_proximal_joint"/>
        <position ctrllimited="true" ctrlrange="+0.0 1.7" forcerange="-1 1" name="R_pinky_intermediate_actuator" joint="R_pinky_intermediate_joint"/>
        <position ctrllimited="true" ctrlrange="+0.0 1.7" forcerange="-1 1" name="R_ring_proximal_actuator" joint="R_ring_proximal_joint"/>
        <position ctrllimited="true" ctrlrange="+0.0 1.7" forcerange="-1 1" name="R_ring_intermediate_actuator" joint="R_ring_intermediate_joint"/>
        <position ctrllimited="true" ctrlrange="-0.1 1.3" forcerange="-1 1" name="R_thumb_proximal_yaw_actuator" joint="R_thumb_proximal_yaw_joint"/>
        <position ctrllimited="true" ctrlrange="+0.0 0.5" forcerange="-1 1" name="R_thumb_proximal_pitch_actuator" joint="R_thumb_proximal_pitch_joint"/>
        <position ctrllimited="true" ctrlrange="+0.0 0.8" forcerange="-1 1" name="R_thumb_intermediate_actuator" joint="R_thumb_intermediate_joint"/>
        <position ctrllimited="true" ctrlrange="+0.0 1.2" forcerange="-1 1" name="R_thumb_distal_actuator" joint="R_thumb_distal_joint"/>



        <!-- <motor ctrllimited="true" ctrlrange="-200 200" name="left_hip_yaw_actuator" joint="left_hip_yaw_joint"/>
        <motor ctrllimited="true" ctrlrange="-200 200" name="left_hip_roll_actuator" joint="left_hip_roll_joint"/>
        <motor ctrllimited="true" ctrlrange="-200 200" name="left_hip_pitch_actuator" joint="left_hip_pitch_joint"/>
        <motor ctrllimited="true" ctrlrange="-300 300" name="left_knee_actuator" joint="left_knee_joint"/>
        <motor ctrllimited="true" ctrlrange="-40 40" name="left_ankle_pitch_actuator" joint="left_ankle_pitch_joint"/>
        <motor ctrllimited="true" ctrlrange="-40 40" name="left_ankle_roll_actuator" joint="left_ankle_roll_joint"/>
        <motor ctrllimited="true" ctrlrange="-200 200" name="right_hip_yaw_actuator" joint="right_hip_yaw_joint"/>
        <motor ctrllimited="true" ctrlrange="-200 200" name="right_hip_roll_actuator" joint="right_hip_roll_joint"/>
        <motor ctrllimited="true" ctrlrange="-200 200" name="right_hip_pitch_actuator" joint="right_hip_pitch_joint"/>
        <motor ctrllimited="true" ctrlrange="-300 300" name="right_knee_actuator" joint="right_knee_joint"/>
        <motor ctrllimited="true" ctrlrange="-40 40" name="right_ankle_pitch_actuator" joint="right_ankle_pitch_joint"/>
        <motor ctrllimited="true" ctrlrange="-40 40" name="right_ankle_roll_actuator" joint="right_ankle_roll_joint"/>
        
        <motor ctrllimited="true" ctrlrange="-200 200" name="torso_actuator" joint="torso_joint"/>

        <motor ctrllimited="true" ctrlrange="-40 40" name="left_shoulder_pitch_actuator" joint="left_shoulder_pitch_joint"/>
        <motor ctrllimited="true" ctrlrange="-40 40" name="left_shoulder_roll_actuator" joint="left_shoulder_roll_joint"/>
        <motor ctrllimited="true" ctrlrange="-18 18" name="left_shoulder_yaw_actuator" joint="left_shoulder_yaw_joint"/>
        <motor ctrllimited="true" ctrlrange="-18 18" name="left_elbow_pitch_actuator" joint="left_elbow_pitch_joint"/>
        <motor ctrllimited="true" ctrlrange="-18 18" name="left_elbow_roll_actuator" joint="left_elbow_roll_joint"/>
        <motor ctrllimited="true" ctrlrange="-19 19" name="left_wrist_pitch_actuator" joint="left_wrist_pitch_joint"/>
        <motor ctrllimited="true" ctrlrange="-19 19" name="left_wrist_yaw_actuator" joint="left_wrist_yaw_joint"/>
        
        <motor ctrllimited="true" ctrlrange="-1 1" name="L_index_proximal_actuator" joint="L_index_proximal_joint"/>
        <motor ctrllimited="true" ctrlrange="-1 1" name="L_index_intermediate_actuator" joint="L_index_intermediate_joint"/>
        <motor ctrllimited="true" ctrlrange="-1 1" name="L_middle_proximal_actuator" joint="L_middle_proximal_joint"/>
        <motor ctrllimited="true" ctrlrange="-1 1" name="L_middle_intermediate_actuator" joint="L_middle_intermediate_joint"/>
        <motor ctrllimited="true" ctrlrange="-1 1" name="L_pinky_proximal_actuator" joint="L_pinky_proximal_joint"/>
        <motor ctrllimited="true" ctrlrange="-1 1" name="L_pinky_intermediate_actuator" joint="L_pinky_intermediate_joint"/>
        <motor ctrllimited="true" ctrlrange="-1 1" name="L_ring_proximal_actuator" joint="L_ring_proximal_joint"/>
        <motor ctrllimited="true" ctrlrange="-1 1" name="L_ring_intermediate_actuator" joint="L_ring_intermediate_joint"/>
        <motor ctrllimited="true" ctrlrange="-1 1" name="L_thumb_proximal_yaw_actuator" joint="L_thumb_proximal_yaw_joint"/>
        <motor ctrllimited="true" ctrlrange="-1 1" name="L_thumb_proximal_pitch_actuator" joint="L_thumb_proximal_pitch_joint"/>
        <motor ctrllimited="true" ctrlrange="-1 1" name="L_thumb_intermediate_actuator" joint="L_thumb_intermediate_joint"/>
        <motor ctrllimited="true" ctrlrange="-1 1" name="L_thumb_distal_actuator" joint="L_thumb_distal_joint"/>

        <motor ctrllimited="true" ctrlrange="-40 40" name="right_shoulder_pitch_actuator" joint="right_shoulder_pitch_joint"/>
        <motor ctrllimited="true" ctrlrange="-40 40" name="right_shoulder_roll_actuator" joint="right_shoulder_roll_joint"/>
        <motor ctrllimited="true" ctrlrange="-18 18" name="right_shoulder_yaw_actuator" joint="right_shoulder_yaw_joint"/>
        <motor ctrllimited="true" ctrlrange="-18 18" name="right_elbow_pitch_actuator" joint="right_elbow_pitch_joint"/>
        <motor ctrllimited="true" ctrlrange="-18 18" name="right_elbow_roll_actuator" joint="right_elbow_roll_joint"/>
        <motor ctrllimited="true" ctrlrange="-19 19" name="right_wrist_pitch_actuator" joint="right_wrist_pitch_joint"/>
        <motor ctrllimited="true" ctrlrange="-19 19" name="right_wrist_yaw_actuator" joint="right_wrist_yaw_joint"/>
        
        <motor ctrllimited="true" ctrlrange="-1 1" name="R_index_proximal_actuator" joint="R_index_proximal_joint"/>
        <motor ctrllimited="true" ctrlrange="-1 1" name="R_index_intermediate_actuator" joint="R_index_intermediate_joint"/>
        <motor ctrllimited="true" ctrlrange="-1 1" name="R_middle_proximal_actuator" joint="R_middle_proximal_joint"/>
        <motor ctrllimited="true" ctrlrange="-1 1" name="R_middle_intermediate_actuator" joint="R_middle_intermediate_joint"/>
        <motor ctrllimited="true" ctrlrange="-1 1" name="R_pinky_proximal_actuator" joint="R_pinky_proximal_joint"/>
        <motor ctrllimited="true" ctrlrange="-1 1" name="R_pinky_intermediate_actuator" joint="R_pinky_intermediate_joint"/>
        <motor ctrllimited="true" ctrlrange="-1 1" name="R_ring_proximal_actuator" joint="R_ring_proximal_joint"/>
        <motor ctrllimited="true" ctrlrange="-1 1" name="R_ring_intermediate_actuator" joint="R_ring_intermediate_joint"/>
        <motor ctrllimited="true" ctrlrange="-1 1" name="R_thumb_proximal_yaw_actuator" joint="R_thumb_proximal_yaw_joint"/>
        <motor ctrllimited="true" ctrlrange="-1 1" name="R_thumb_proximal_pitch_actuator" joint="R_thumb_proximal_pitch_joint"/>
        <motor ctrllimited="true" ctrlrange="-1 1" name="R_thumb_intermediate_actuator" joint="R_thumb_intermediate_joint"/>
        <motor ctrllimited="true" ctrlrange="-1 1" name="R_thumb_distal_actuator" joint="R_thumb_distal_joint"/> -->


    </actuator>
</mujoco>