<mujoco model="model">
  <compiler angle="radian"/>
  <asset>
    <texture type="2d" name="sink_tap_image0" file="../objects/bigym/sink_tap/visuals/image0.png"/>
    <material name="kitchen_sink" texture="sink_tap_image0" specular="0.5" shininess="0.25"/>
    <mesh file="../objects/bigym/sink_tap/visuals/model_0.obj" name="sink_tap_model_0_vis" scale="0.5 0.5 0.5"/>
    <mesh file="../objects/bigym/sink_tap/visuals/spout_0.obj" name="spout_0_vis" scale="0.5 0.5 0.5"/>
    <mesh file="../objects/bigym/sink_tap/visuals/handle_0.obj" name="sink_tap_handle_0_vis" scale="0.5 0.5 0.5"/>
  </asset>
  <default>
    <default class="sink_tap_visual">
      <geom conaffinity="0" contype="0" group="1" type="mesh"/>
    </default>
    <default class="sink_tap_collision">
      <geom group="0" rgba="0.5 0 0 0"/>
    </default>
  </default>
  <worldbody>
    <body name="sink_tap" pos="0.50 0 1.24" quat="0.707 0 0 -0.707" >
      <!-- exterior bounding box points -->
      <site rgba="0 0 0 1" size="0.01" pos="-0.25 -0.2125 -0.13075" name="sink_tap_ext_p0"/>
      <site rgba="1 0 0 1" size="0.01" pos="0.25 -0.2125 -0.13075" name="sink_tap_ext_px"/>
      <site rgba="0 1 0 1" size="0.01" pos="-0.25 0.2125 -0.13075" name="sink_tap_ext_py"/>
      <site rgba="0 0 1 1" size="0.01" pos="-0.25 -0.2125 -0.014" name="sink_tap_ext_pz"/>
      <!-- interior bounding box points -->
      <site rgba="0.5 0.5 0.5 1" size="0.01" pos="-0.225 -0.1875 -0.1225" name="sink_tap_int_p0"/>
      <site rgba="1 1 0 1" size="0.01" pos="0.225 -0.1875 -0.1225" name="sink_tap_int_px"/>
      <site rgba="0 1 1 1" size="0.01" pos="-0.225 0.145 -0.1225" name="sink_tap_int_py"/>
      <site rgba="1 0 1 1" size="0.01" pos="-0.225 -0.1875 -0.014" name="sink_tap_int_pz"/>
      <body name="tap_object">
        <geom solimp="0.998 0.998 0.001" solref="0.001 1" density="100" friction="0.95 0.3 0.1" type="mesh" mesh="sink_tap_model_0_vis" material="kitchen_sink" class="sink_tap_visual"/>
        <!-- Bottom -->
        <geom class="sink_tap_collision" type="box" pos="0 -0.02 -0.13" size="0.21 0.16 0.0075" name="bottom"/>
        <!-- Left Wall -->
        <geom class="sink_tap_collision" type="box" pos="-0.225 -0.02 -0.0725" size="0.0075 0.16 0.06" axisangle="0 1 0 -0.17"/>
        <!-- Right Wall -->
        <geom class="sink_tap_collision" type="box" pos="0.225 -0.02 -0.0725" size="0.0075 0.16 0.06" axisangle="0 1 0 0.17"/>
        <!-- Back Wall -->
        <geom class="sink_tap_collision" type="box" pos="0 0.145 -0.0725" size="0.23 0.0075 0.06" axisangle="1 0 0 -0.10"/>
        <!-- Front Wall -->
        <geom class="sink_tap_collision" type="box" pos="0 -0.1875 -0.0725" size="0.23 0.0075 0.06" axisangle="1 0 0 0.10"/>
        <!-- Back Ledge -->
        <geom class="sink_tap_collision" type="box" pos="0 0.178 -0.0175" size="0.25 0.034 0.0035"/>
        <!-- Front Ledge -->
        <geom class="sink_tap_collision" type="box" pos="0 -0.2025 -0.0175" size="0.25 0.01 0.0035"/>
        <!-- Right Ledge -->
        <geom class="sink_tap_collision" type="box" pos="0.24 0 -0.0175" size="0.01 0.2 0.0035"/>
        <!-- Left Ledge -->
        <geom class="sink_tap_collision" type="box" pos="-0.24 0 -0.0175" size="0.01 0.2 0.0035"/>
        <!-- Faucet Base -->
        <geom class="sink_tap_collision" type="box" pos="0 0.184 -0.00585" size="0.111 0.0223 0.00825"/>
        <body name="spout">
          <joint axis="0 0 1" limited="true" name="spout_joint" range="-1.57 1.57" pos="0 0.184 0.0225" armature="2" damping="10"/>
          <geom solimp="0.998 0.998 0.001" solref="0.001 1" density="100" friction="0.95 0.3 0.1" type="mesh" mesh="spout_0_vis" material="kitchen_sink" class="sink_tap_visual"/>
          <geom class="sink_tap_collision" type="cylinder" pos="0 0.184 0.0225" size="0.017 0.017 0"/>
          <!-- <geom class="sink_tap_collision" type="box" pos="0 0.1075 0.06475" size="0.0115 0.08 0.006"/> -->
          <geom class="sink_tap_collision" type="box" pos="0 0.025 0.11" size="0.0115 0.0195 0.006"/>
          <geom class="sink_tap_collision" type="cylinder" pos="0 0.01675 0.10125" size="0.01 0.00275 0"/>
          <!-- <site type="cylinder" rgba="0.5 0.75 1 1" pos="0.0 0.03 -0.03" size="0.01 0.25" name="water"/> -->
        </body>
        <body name="handle">
          <joint axis="-1 0 0" limited="true" type="hinge" name="handle_joint" range="0 0.26" pos="0 0.184 0.055" armature="2" damping="10"/>
          <joint axis="0 0 1" limited="true" type="hinge" name="handle_temp_joint" range="-0.395 0.395" pos="0 0.184 0.05825" armature="2" damping="10"/>
          <geom solimp="0.998 0.998 0.001" solref="0.001 1" density="100" friction="0.95 0.3 0.1" type="mesh" mesh="sink_tap_handle_0_vis" material="kitchen_sink" class="sink_tap_visual"/>
          <!-- <geom class="sink_tap_collision" type="cylinder" pos="0 0.184 0.05825" size="0.017 0.00825 0" axisangle="1 0 0 0.17"/> -->
          <geom class="sink_tap_collision" type="box" pos="0 0.1465 0.104" size="0.0115 0.065 0.00325" axisangle="1 0 0 -0.63" name="handle_main"/>
        </body>
      </body>
    </body>
  </worldbody>
</mujoco>
